Workbook

Sheet Assumptions
A1: MMM Scoring — Assumptions
A2: 30yr Fixed Rate (%) | B2: 0.0747
A3: Down Payment (%) | B3: 0.25
A4: Expense Ratio (%) | B4: 0.35
A6: Blue cells = inputs you can change. All scores recalculate automatically.

Sheet Scored Listings
A1: Listing Link | B1: Address | C1: Zip | D1: County | E1: Type | F1: Units | G1: Price ($) | H1: Est. Rent ($/mo) | I1: 1% Ratio | J1: NOI ($/mo) | K1: Monthly Mortgage ($/mo) | L1: Net Cash Flow ($/mo) | M1: 1% Score | N1: CF Score | O1: Location Score | P1: Total Score | Q1: MLS ID | R1: STR Flag | S1: Previously Featured?
A2: =HYPERLINK("https://www.google.com/search?q=A11965762+Miami+MLS+listing", "A11965762") | B2: 2425 NW 28th St | C2: 33142 | D2: Miami-Dade County | E2: Triplex | F2: 3 | G2: 614000 | H2: 6900 | I2: =H2/G2 | J2: =H2*(1-Assumptions!$B$4) | K2: =PMT(Assumptions!$B$2/12, 360, -G2*(1-Assumptions!$B$3)) | L2: =J2+K2 | M2: =IF(I2>=0.01,50,IF(I2>=0.0095,37,IF(I2>=0.009,25,12))) | N2: =IF(L2>=2000,30,IF(L2>=1000,20,IF(L2>=500,10,5))) | O2: 20 | P2: =M2+N2+O2 | Q2: A11965762
A3: =HYPERLINK("https://www.google.com/search?q=A11960470+Miami+MLS+listing", "A11960470") | B3: 6241 NW Miami Pl | C3: 33150 | D3: Miami-Dade County | E3: Duplex | F3: 2 | G3: 899000 | H3: 9800 | I3: =H3/G3 | J3: =H3*(1-Assumptions!$B$4) | K3: =PMT(Assumptions!$B$2/12, 360, -G3*(1-Assumptions!$B$3)) | L3: =J3+K3 | M3: =IF(I3>=0.01,50,IF(I3>=0.0095,37,IF(I3>=0.009,25,12))) | N3: =IF(L3>=2000,30,IF(L3>=1000,20,IF(L3>=500,10,5))) | O3: 20 | P3: =M3+N3+O3 | Q3: A11960470
A4: =HYPERLINK("https://www.google.com/search?q=A11969029+Miami+MLS+listing", "A11969029") | B4: 356 SW 2nd Pl | C4: 33060 | D4: Broward County | E4: Fourplex | F4: 4 | G4: 750000 | H4: 7650 | I4: =H4/G4 | J4: =H4*(1-Assumptions!$B$4) | K4: =PMT(Assumptions!$B$2/12, 360, -G4*(1-Assumptions!$B$3)) | L4: =J4+K4 | M4: =IF(I4>=0.01,50,IF(I4>=0.0095,37,IF(I4>=0.009,25,12))) | N4: =IF(L4>=2000,30,IF(L4>=1000,20,IF(L4>=500,10,5))) | O4: 13 | P4: =M4+N4+O4 | Q4: A11969029
A5: =HYPERLINK("https://www.google.com/search?q=A11919736+Miami+MLS+listing", "A11919736") | B5: 2601 N 66th Ave | C5: 33024 | D5: Broward County | E5: Fourplex | F5: 4 | G5: 615000 | H5: 7500 | I5: =H5/G5 | J5: =H5*(1-Assumptions!$B$4) | K5: =PMT(Assumptions!$B$2/12, 360, -G5*(1-Assumptions!$B$3)) | L5: =J5+K5 | M5: =IF(I5>=0.01,50,IF(I5>=0.0095,37,IF(I5>=0.009,25,12))) | N5: =IF(L5>=2000,30,IF(L5>=1000,20,IF(L5>=500,10,5))) | O5: 13 | P5: =M5+N5+O5 | Q5: A11919736
A6: =HYPERLINK("https://www.google.com/search?q=A11744047+Miami+MLS+listing", "A11744047") | B6: 655 NE 135th St | C6: 33161 | D6: Miami-Dade County | E6: Duplex | F6: 2 | G6: 660000 | H6: 6700 | I6: =H6/G6 | J6: =H6*(1-Assumptions!$B$4) | K6: =PMT(Assumptions!$B$2/12, 360, -G6*(1-Assumptions!$B$3)) | L6: =J6+K6 | M6: =IF(I6>=0.01,50,IF(I6>=0.0095,37,IF(I6>=0.009,25,12))) | N6: =IF(L6>=2000,30,IF(L6>=1000,20,IF(L6>=500,10,5))) | O6: 20 | P6: =M6+N6+O6 | Q6: A11744047
A7: =HYPERLINK("https://www.google.com/search?q=A11922821+Miami+MLS+listing", "A11922821") | B7: 2912 NW 32nd St | C7: 33142 | D7: Miami-Dade County | E7: Duplex | F7: 2 | G7: 500000 | H7: 5000 | I7: =H7/G7 | J7: =H7*(1-Assumptions!$B$4) | K7: =PMT(Assumptions!$B$2/12, 360, -G7*(1-Assumptions!$B$3)) | L7: =J7+K7 | M7: =IF(I7>=0.01,50,IF(I7>=0.0095,37,IF(I7>=0.009,25,12))) | N7: =IF(L7>=2000,30,IF(L7>=1000,20,IF(L7>=500,10,5))) | O7: 20 | P7: =M7+N7+O7 | Q7: A11922821
A8: =HYPERLINK("https://www.google.com/search?q=A11901546+Miami+MLS+listing", "A11901546") | B8: 2930 NW 14th Ave | C8: 33142 | D8: Miami-Dade County | E8: Fourplex | F8: 4 | G8: 689500 | H8: 6940 | I8: =H8/G8 | J8: =H8*(1-Assumptions!$B$4) | K8: =PMT(Assumptions!$B$2/12, 360, -G8*(1-Assumptions!$B$3)) | L8: =J8+K8 | M8: =IF(I8>=0.01,50,IF(I8>=0.0095,37,IF(I8>=0.009,25,12))) | N8: =IF(L8>=2000,30,IF(L8>=1000,20,IF(L8>=500,10,5))) | O8: 20 | P8: =M8+N8+O8 | Q8: A11901546
A9: =HYPERLINK("https://www.google.com/search?q=A11839261+Miami+MLS+listing", "A11839261") | B9: 2240 Simms St | C9: 33020 | D9: Broward County | E9: Fourplex | F9: 4 | G9: 845000 | H9: 8396 | I9: =H9/G9 | J9: =H9*(1-Assumptions!$B$4) | K9: =PMT(Assumptions!$B$2/12, 360, -G9*(1-Assumptions!$B$3)) | L9: =J9+K9 | M9: =IF(I9>=0.01,50,IF(I9>=0.0095,37,IF(I9>=0.009,25,12))) | N9: =IF(L9>=2000,30,IF(L9>=1000,20,IF(L9>=500,10,5))) | O9: 13 | P9: =M9+N9+O9 | Q9: A11839261
A10: =HYPERLINK("https://www.google.com/search?q=A11967277+Miami+MLS+listing", "A11967277") | B10: 4381 Purdy Ln | C10: 33406 | D10: Palm Beach County | E10: Triplex | F10: 3 | G10: 750000 | H10: 7250 | I10: =H10/G10 | J10: =H10*(1-Assumptions!$B$4) | K10: =PMT(Assumptions!$B$2/12, 360, -G10*(1-Assumptions!$B$3)) | L10: =J10+K10 | M10: =IF(I10>=0.01,50,IF(I10>=0.0095,37,IF(I10>=0.009,25,12))) | N10: =IF(L10>=2000,30,IF(L10>=1000,20,IF(L10>=500,10,5))) | O10: 13 | P10: =M10+N10+O10 | Q10: A11967277
A11: =HYPERLINK("https://www.google.com/search?q=A11969394+Miami+MLS+listing", "A11969394") | B11: 208 SW 1st Ct | C11: 33060 | D11: Broward County | E11: Triplex | F11: 3 | G11: 700000 | H11: 6800 | I11: =H11/G11 | J11: =H11*(1-Assumptions!$B$4) | K11: =PMT(Assumptions!$B$2/12, 360, -G11*(1-Assumptions!$B$3)) | L11: =J11+K11 | M11: =IF(I11>=0.01,50,IF(I11>=0.0095,37,IF(I11>=0.009,25,12))) | N11: =IF(L11>=2000,30,IF(L11>=1000,20,IF(L11>=500,10,5))) | O11: 13 | P11: =M11+N11+O11 | Q11: A11969394
A12: =HYPERLINK("https://www.google.com/search?q=A11893787+Miami+MLS+listing", "A11893787") | B12: 1102 NW 103rd Street | C12: 33150 | D12: Miami-Dade County | E12: Triplex | F12: 3 | G12: 749000 | H12: 6975 | I12: =H12/G12 | J12: =H12*(1-Assumptions!$B$4) | K12: =PMT(Assumptions!$B$2/12, 360, -G12*(1-Assumptions!$B$3)) | L12: =J12+K12 | M12: =IF(I12>=0.01,50,IF(I12>=0.0095,37,IF(I12>=0.009,25,12))) | N12: =IF(L12>=2000,30,IF(L12>=1000,20,IF(L12>=500,10,5))) | O12: 20 | P12: =M12+N12+O12 | Q12: A11893787
A13: =HYPERLINK("https://www.google.com/search?q=A11893641+Miami+MLS+listing", "A11893641") | B13: 10290 SW 174th Ter | C13: 33157 | D13: Miami-Dade County | E13: Duplex | F13: 2 | G13: 699900 | H13: 6400 | I13: =H13/G13 | J13: =H13*(1-Assumptions!$B$4) | K13: =PMT(Assumptions!$B$2/12, 360, -G13*(1-Assumptions!$B$3)) | L13: =J13+K13 | M13: =IF(I13>=0.01,50,IF(I13>=0.0095,37,IF(I13>=0.009,25,12))) | N13: =IF(L13>=2000,30,IF(L13>=1000,20,IF(L13>=500,10,5))) | O13: 16 | P13: =M13+N13+O13 | Q13: A11893641
A14: =HYPERLINK("https://www.google.com/search?q=A11889559+Miami+MLS+listing", "A11889559") | B14: 276 E 12th St | C14: 33010 | D14: Miami-Dade County | E14: Triplex | F14: 3 | G14: 820000 | H14: 7400 | I14: =H14/G14 | J14: =H14*(1-Assumptions!$B$4) | K14: =PMT(Assumptions!$B$2/12, 360, -G14*(1-Assumptions!$B$3)) | L14: =J14+K14 | M14: =IF(I14>=0.01,50,IF(I14>=0.0095,37,IF(I14>=0.009,25,12))) | N14: =IF(L14>=2000,30,IF(L14>=1000,20,IF(L14>=500,10,5))) | O14: 16 | P14: =M14+N14+O14 | Q14: A11889559
A15: =HYPERLINK("https://www.google.com/search?q=A11977765+Miami+MLS+listing", "A11977765") | B15: 3021 NE 7th Ave | C15: 33064 | D15: Broward County | E15: Fourplex | F15: 4 | G15: 899000 | H15: 8200 | I15: =H15/G15 | J15: =H15*(1-Assumptions!$B$4) | K15: =PMT(Assumptions!$B$2/12, 360, -G15*(1-Assumptions!$B$3)) | L15: =J15+K15 | M15: =IF(I15>=0.01,50,IF(I15>=0.0095,37,IF(I15>=0.009,25,12))) | N15: =IF(L15>=2000,30,IF(L15>=1000,20,IF(L15>=500,10,5))) | O15: 13 | P15: =M15+N15+O15 | Q15: A11977765
A16: =HYPERLINK("https://www.google.com/search?q=A11943542+Miami+MLS+listing", "A11943542") | B16: 3270 SW 7th St | C16: 33135 | D16: Miami-Dade County | E16: Duplex | F16: 2 | G16: 1125000 | H16: 6400 | I16: =H16/G16 | J16: =H16*(1-Assumptions!$B$4) | K16: =PMT(Assumptions!$B$2/12, 360, -G16*(1-Assumptions!$B$3)) | L16: =J16+K16 | M16: =IF(I16>=0.01,50,IF(I16>=0.0095,37,IF(I16>=0.009,25,12))) | N16: =IF(L16>=2000,30,IF(L16>=1000,20,IF(L16>=500,10,5))) | O16: 20 | P16: =M16+N16+O16 | Q16: A11943542
A17: =HYPERLINK("https://www.google.com/search?q=A11923026+Miami+MLS+listing", "A11923026") | B17: 2416 NW 79th Ter | C17: 33147 | D17: Miami-Dade County | E17: Triplex | F17: 3 | G17: 759000 | H17: 6482 | I17: =H17/G17 | J17: =H17*(1-Assumptions!$B$4) | K17: =PMT(Assumptions!$B$2/12, 360, -G17*(1-Assumptions!$B$3)) | L17: =J17+K17 | M17: =IF(I17>=0.01,50,IF(I17>=0.0095,37,IF(I17>=0.009,25,12))) | N17: =IF(L17>=2000,30,IF(L17>=1000,20,IF(L17>=500,10,5))) | O17: 20 | P17: =M17+N17+O17 | Q17: A11923026
A18: =HYPERLINK("https://www.google.com/search?q=A11952604+Miami+MLS+listing", "A11952604") | B18: 3330 NW 4th St | C18: 33125 | D18: Miami-Dade County | E18: Duplex | F18: 2 | G18: 795000 | H18: 5200 | I18: =H18/G18 | J18: =H18*(1-Assumptions!$B$4) | K18: =PMT(Assumptions!$B$2/12, 360, -G18*(1-Assumptions!$B$3)) | L18: =J18+K18 | M18: =IF(I18>=0.01,50,IF(I18>=0.0095,37,IF(I18>=0.009,25,12))) | N18: =IF(L18>=2000,30,IF(L18>=1000,20,IF(L18>=500,10,5))) | O18: 20 | P18: =M18+N18+O18 | Q18: A11952604
A19: =HYPERLINK("https://www.google.com/search?q=A11868974+Miami+MLS+listing", "A11868974") | B19: 1255 NE 110th Ter | C19: 33161 | D19: Miami-Dade County | E19: Duplex | F19: 2 | G19: 660000 | H19: 5100 | I19: =H19/G19 | J19: =H19*(1-Assumptions!$B$4) | K19: =PMT(Assumptions!$B$2/12, 360, -G19*(1-Assumptions!$B$3)) | L19: =J19+K19 | M19: =IF(I19>=0.01,50,IF(I19>=0.0095,37,IF(I19>=0.009,25,12))) | N19: =IF(L19>=2000,30,IF(L19>=1000,20,IF(L19>=500,10,5))) | O19: 20 | P19: =M19+N19+O19 | Q19: A11868974
A20: =HYPERLINK("https://www.google.com/search?q=A11911368+Miami+MLS+listing", "A11911368") | B20: 1247 NW 28th St | C20: 33142 | D20: Miami-Dade County | E20: Duplex | F20: 2 | G20: 825000 | H20: 6400 | I20: =H20/G20 | J20: =H20*(1-Assumptions!$B$4) | K20: =PMT(Assumptions!$B$2/12, 360, -G20*(1-Assumptions!$B$3)) | L20: =J20+K20 | M20: =IF(I20>=0.01,50,IF(I20>=0.0095,37,IF(I20>=0.009,25,12))) | N20: =IF(L20>=2000,30,IF(L20>=1000,20,IF(L20>=500,10,5))) | O20: 20 | P20: =M20+N20+O20 | Q20: A11911368
A21: =HYPERLINK("https://www.google.com/search?q=A11854508+Miami+MLS+listing", "A11854508") | B21: 1701 SW 21st St | C21: 33145 | D21: Miami-Dade County | E21: Duplex | F21: 2 | G21: 899000 | H21: 5100 | I21: =H21/G21 | J21: =H21*(1-Assumptions!$B$4) | K21: =PMT(Assumptions!$B$2/12, 360, -G21*(1-Assumptions!$B$3)) | L21: =J21+K21 | M21: =IF(I21>=0.01,50,IF(I21>=0.0095,37,IF(I21>=0.009,25,12))) | N21: =IF(L21>=2000,30,IF(L21>=1000,20,IF(L21>=500,10,5))) | O21: 20 | P21: =M21+N21+O21 | Q21: A11854508
A22: =HYPERLINK("https://www.google.com/search?q=A11957385+Miami+MLS+listing", "A11957385") | B22: 1362 SW 2nd St | C22: 33135 | D22: Miami-Dade County | E22: Fourplex | F22: 4 | G22: 3990000 | H22: 5100 | I22: =H22/G22 | J22: =H22*(1-Assumptions!$B$4) | K22: =PMT(Assumptions!$B$2/12, 360, -G22*(1-Assumptions!$B$3)) | L22: =J22+K22 | M22: =IF(I22>=0.01,50,IF(I22>=0.0095,37,IF(I22>=0.009,25,12))) | N22: =IF(L22>=2000,30,IF(L22>=1000,20,IF(L22>=500,10,5))) | O22: 20 | P22: =M22+N22+O22 | Q22: A11957385
A23: =HYPERLINK("https://www.google.com/search?q=A11389399+Miami+MLS+listing", "A11389399") | B23: 2855 NW 22nd Ave | C23: 33142 | D23: Miami-Dade County | E23: Fourplex | F23: 4 | G23: 910000 | H23: 6425 | I23: =H23/G23 | J23: =H23*(1-Assumptions!$B$4) | K23: =PMT(Assumptions!$B$2/12, 360, -G23*(1-Assumptions!$B$3)) | L23: =J23+K23 | M23: =IF(I23>=0.01,50,IF(I23>=0.0095,37,IF(I23>=0.009,25,12))) | N23: =IF(L23>=2000,30,IF(L23>=1000,20,IF(L23>=500,10,5))) | O23: 20 | P23: =M23+N23+O23 | Q23: A11389399
A24: =HYPERLINK("https://www.google.com/search?q=A11965310+Miami+MLS+listing", "A11965310") | B24: 1220-1222 NE 110th Ter | C24: 33161 | D24: Miami-Dade County | E24: Triplex | F24: 3 | G24: 749000 | H24: 5095 | I24: =H24/G24 | J24: =H24*(1-Assumptions!$B$4) | K24: =PMT(Assumptions!$B$2/12, 360, -G24*(1-Assumptions!$B$3)) | L24: =J24+K24 | M24: =IF(I24>=0.01,50,IF(I24>=0.0095,37,IF(I24>=0.009,25,12))) | N24: =IF(L24>=2000,30,IF(L24>=1000,20,IF(L24>=500,10,5))) | O24: 20 | P24: =M24+N24+O24 | Q24: A11965310
A25: =HYPERLINK("https://www.google.com/search?q=A11962645+Miami+MLS+listing", "A11962645") | B25: 2900 SW 4th St | C25: 33135 | D25: Miami-Dade County | E25: Duplex | F25: 2 | G25: 975000 | H25: 5050 | I25: =H25/G25 | J25: =H25*(1-Assumptions!$B$4) | K25: =PMT(Assumptions!$B$2/12, 360, -G25*(1-Assumptions!$B$3)) | L25: =J25+K25 | M25: =IF(I25>=0.01,50,IF(I25>=0.0095,37,IF(I25>=0.009,25,12))) | N25: =IF(L25>=2000,30,IF(L25>=1000,20,IF(L25>=500,10,5))) | O25: 20 | P25: =M25+N25+O25 | Q25: A11962645
A26: =HYPERLINK("https://www.google.com/search?q=A11818575+Miami+MLS+listing", "A11818575") | B26: 77 Northwest Blvd | C26: 33126 | D26: Miami-Dade County | E26: Triplex | F26: 3 | G26: 1025000 | H26: 5050 | I26: =H26/G26 | J26: =H26*(1-Assumptions!$B$4) | K26: =PMT(Assumptions!$B$2/12, 360, -G26*(1-Assumptions!$B$3)) | L26: =J26+K26 | M26: =IF(I26>=0.01,50,IF(I26>=0.0095,37,IF(I26>=0.009,25,12))) | N26: =IF(L26>=2000,30,IF(L26>=1000,20,IF(L26>=500,10,5))) | O26: 20 | P26: =M26+N26+O26 | Q26: A11818575
A27: =HYPERLINK("https://www.google.com/search?q=A11913807+Miami+MLS+listing", "A11913807") | B27: 2800 NW 48th St | C27: 33142 | D27: Miami-Dade County | E27: Duplex | F27: 2 | G27: 749900 | H27: 5048 | I27: =H27/G27 | J27: =H27*(1-Assumptions!$B$4) | K27: =PMT(Assumptions!$B$2/12, 360, -G27*(1-Assumptions!$B$3)) | L27: =J27+K27 | M27: =IF(I27>=0.01,50,IF(I27>=0.0095,37,IF(I27>=0.009,25,12))) | N27: =IF(L27>=2000,30,IF(L27>=1000,20,IF(L27>=500,10,5))) | O27: 20 | P27: =M27+N27+O27 | Q27: A11913807
A28: =HYPERLINK("https://www.google.com/search?q=A11950698+Miami+MLS+listing", "A11950698") | B28: 2930 SW 11th ST | C28: 33135 | D28: Miami-Dade County | E28: Duplex | F28: 2 | G28: 965000 | H28: 5000 | I28: =H28/G28 | J28: =H28*(1-Assumptions!$B$4) | K28: =PMT(Assumptions!$B$2/12, 360, -G28*(1-Assumptions!$B$3)) | L28: =J28+K28 | M28: =IF(I28>=0.01,50,IF(I28>=0.0095,37,IF(I28>=0.009,25,12))) | N28: =IF(L28>=2000,30,IF(L28>=1000,20,IF(L28>=500,10,5))) | O28: 20 | P28: =M28+N28+O28 | Q28: A11950698
A29: =HYPERLINK("https://www.google.com/search?q=A11898915+Miami+MLS+listing", "A11898915") | B29: 1230 NE 148th St | C29: 33161 | D29: Miami-Dade County | E29: Duplex | F29: 2 | G29: 695000 | H29: 5000 | I29: =H29/G29 | J29: =H29*(1-Assumptions!$B$4) | K29: =PMT(Assumptions!$B$2/12, 360, -G29*(1-Assumptions!$B$3)) | L29: =J29+K29 | M29: =IF(I29>=0.01,50,IF(I29>=0.0095,37,IF(I29>=0.009,25,12))) | N29: =IF(L29>=2000,30,IF(L29>=1000,20,IF(L29>=500,10,5))) | O29: 20 | P29: =M29+N29+O29 | Q29: A11898915
A30: =HYPERLINK("https://www.google.com/search?q=A11857462+Miami+MLS+listing", "A11857462") | B30: 2367 SW 19th St | C30: 33145 | D30: Miami-Dade County | E30: Duplex | F30: 2 | G30: 1500000 | H30: 5000 | I30: =H30/G30 | J30: =H30*(1-Assumptions!$B$4) | K30: =PMT(Assumptions!$B$2/12, 360, -G30*(1-Assumptions!$B$3)) | L30: =J30+K30 | M30: =IF(I30>=0.01,50,IF(I30>=0.0095,37,IF(I30>=0.009,25,12))) | N30: =IF(L30>=2000,30,IF(L30>=1000,20,IF(L30>=500,10,5))) | O30: 20 | P30: =M30+N30+O30 | Q30: A11857462
A31: =HYPERLINK("https://www.google.com/search?q=A11873597+Miami+MLS+listing", "A11873597") | B31: 272 NW 59th Street | C31: 33127 | D31: Miami-Dade County | E31: Duplex | F31: 2 | G31: 1400000 | H31: 6500 | I31: =H31/G31 | J31: =H31*(1-Assumptions!$B$4) | K31: =PMT(Assumptions!$B$2/12, 360, -G31*(1-Assumptions!$B$3)) | L31: =J31+K31 | M31: =IF(I31>=0.01,50,IF(I31>=0.0095,37,IF(I31>=0.009,25,12))) | N31: =IF(L31>=2000,30,IF(L31>=1000,20,IF(L31>=500,10,5))) | O31: 20 | P31: =M31+N31+O31 | Q31: A11873597
A32: =HYPERLINK("https://www.google.com/search?q=A11870712+Miami+MLS+listing", "A11870712") | B32: 1450 NW 35th St | C32: 33142 | D32: Miami-Dade County | E32: Duplex | F32: 2 | G32: 679900 | H32: 5295 | I32: =H32/G32 | J32: =H32*(1-Assumptions!$B$4) | K32: =PMT(Assumptions!$B$2/12, 360, -G32*(1-Assumptions!$B$3)) | L32: =J32+K32 | M32: =IF(I32>=0.01,50,IF(I32>=0.0095,37,IF(I32>=0.009,25,12))) | N32: =IF(L32>=2000,30,IF(L32>=1000,20,IF(L32>=500,10,5))) | O32: 20 | P32: =M32+N32+O32 | Q32: A11870712
A33: =HYPERLINK("https://www.google.com/search?q=A11937235+Miami+MLS+listing", "A11937235") | B33: 890 NW 55th St | C33: 33127 | D33: Miami-Dade County | E33: Duplex | F33: 2 | G33: 795000 | H33: 5000 | I33: =H33/G33 | J33: =H33*(1-Assumptions!$B$4) | K33: =PMT(Assumptions!$B$2/12, 360, -G33*(1-Assumptions!$B$3)) | L33: =J33+K33 | M33: =IF(I33>=0.01,50,IF(I33>=0.0095,37,IF(I33>=0.009,25,12))) | N33: =IF(L33>=2000,30,IF(L33>=1000,20,IF(L33>=500,10,5))) | O33: 20 | P33: =M33+N33+O33 | Q33: A11937235
A34: =HYPERLINK("https://www.google.com/search?q=A11974034+Miami+MLS+listing", "A11974034") | B34: 7001 NW 6th Ave | C34: 33150 | D34: Miami-Dade County | E34: Duplex | F34: 2 | G34: 599000 | H34: 5000 | I34: =H34/G34 | J34: =H34*(1-Assumptions!$B$4) | K34: =PMT(Assumptions!$B$2/12, 360, -G34*(1-Assumptions!$B$3)) | L34: =J34+K34 | M34: =IF(I34>=0.01,50,IF(I34>=0.0095,37,IF(I34>=0.009,25,12))) | N34: =IF(L34>=2000,30,IF(L34>=1000,20,IF(L34>=500,10,5))) | O34: 20 | P34: =M34+N34+O34 | Q34: A11974034
A35: =HYPERLINK("https://www.google.com/search?q=A11908596+Miami+MLS+listing", "A11908596") | B35: 5511 NW 5th Ct | C35: 33127 | D35: Miami-Dade County | E35: Duplex | F35: 2 | G35: 749000 | H35: 4950 | I35: =H35/G35 | J35: =H35*(1-Assumptions!$B$4) | K35: =PMT(Assumptions!$B$2/12, 360, -G35*(1-Assumptions!$B$3)) | L35: =J35+K35 | M35: =IF(I35>=0.01,50,IF(I35>=0.0095,37,IF(I35>=0.009,25,12))) | N35: =IF(L35>=2000,30,IF(L35>=1000,20,IF(L35>=500,10,5))) | O35: 20 | P35: =M35+N35+O35 | Q35: A11908596
A36: =HYPERLINK("https://www.google.com/search?q=A11962171+Miami+MLS+listing", "A11962171") | B36: 201 S Biscayne River Dr #0 | C36: 33169 | D36: Miami-Dade County | E36: Duplex | F36: 2 | G36: 980000 | H36: 4950 | I36: =H36/G36 | J36: =H36*(1-Assumptions!$B$4) | K36: =PMT(Assumptions!$B$2/12, 360, -G36*(1-Assumptions!$B$3)) | L36: =J36+K36 | M36: =IF(I36>=0.01,50,IF(I36>=0.0095,37,IF(I36>=0.009,25,12))) | N36: =IF(L36>=2000,30,IF(L36>=1000,20,IF(L36>=500,10,5))) | O36: 20 | P36: =M36+N36+O36 | Q36: A11962171
A37: =HYPERLINK("https://www.google.com/search?q=A11612506+Miami+MLS+listing", "A11612506") | B37: 3100 NW 92nd St | C37: 33147 | D37: Miami-Dade County | E37: Duplex | F37: 2 | G37: 564000 | H37: 4900 | I37: =H37/G37 | J37: =H37*(1-Assumptions!$B$4) | K37: =PMT(Assumptions!$B$2/12, 360, -G37*(1-Assumptions!$B$3)) | L37: =J37+K37 | M37: =IF(I37>=0.01,50,IF(I37>=0.0095,37,IF(I37>=0.009,25,12))) | N37: =IF(L37>=2000,30,IF(L37>=1000,20,IF(L37>=500,10,5))) | O37: 20 | P37: =M37+N37+O37 | Q37: A11612506
A38: =HYPERLINK("https://www.google.com/search?q=A11819098+Miami+MLS+listing", "A11819098") | B38: 829 SW 19th Ave | C38: 33135 | D38: Miami-Dade County | E38: Fourplex | F38: 4 | G38: 2200000 | H38: 4900 | I38: =H38/G38 | J38: =H38*(1-Assumptions!$B$4) | K38: =PMT(Assumptions!$B$2/12, 360, -G38*(1-Assumptions!$B$3)) | L38: =J38+K38 | M38: =IF(I38>=0.01,50,IF(I38>=0.0095,37,IF(I38>=0.009,25,12))) | N38: =IF(L38>=2000,30,IF(L38>=1000,20,IF(L38>=500,10,5))) | O38: 20 | P38: =M38+N38+O38 | Q38: A11819098
A39: =HYPERLINK("https://www.google.com/search?q=A11964838+Miami+MLS+listing", "A11964838") | B39: 36 NW 151st St | C39: 33169 | D39: Miami-Dade County | E39: Duplex | F39: 2 | G39: 725000 | H39: 4850 | I39: =H39/G39 | J39: =H39*(1-Assumptions!$B$4) | K39: =PMT(Assumptions!$B$2/12, 360, -G39*(1-Assumptions!$B$3)) | L39: =J39+K39 | M39: =IF(I39>=0.01,50,IF(I39>=0.0095,37,IF(I39>=0.009,25,12))) | N39: =IF(L39>=2000,30,IF(L39>=1000,20,IF(L39>=500,10,5))) | O39: 20 | P39: =M39+N39+O39 | Q39: A11964838
A40: =HYPERLINK("https://www.google.com/search?q=A11811435+Miami+MLS+listing", "A11811435") | B40: 1237 NW 33rd Ave | C40: 33125 | D40: Miami-Dade County | E40: Duplex | F40: 2 | G40: 850000 | H40: 4800 | I40: =H40/G40 | J40: =H40*(1-Assumptions!$B$4) | K40: =PMT(Assumptions!$B$2/12, 360, -G40*(1-Assumptions!$B$3)) | L40: =J40+K40 | M40: =IF(I40>=0.01,50,IF(I40>=0.0095,37,IF(I40>=0.009,25,12))) | N40: =IF(L40>=2000,30,IF(L40>=1000,20,IF(L40>=500,10,5))) | O40: 20 | P40: =M40+N40+O40 | Q40: A11811435
...

Sheet Excluded
A1: Address | B1: MLS ID | C1: Reason Excluded
A2: 414 SW 15th Ave | B2: A11856786 | C2: Incomplete Data
A3: 676 SW 1st St | B3: A11705841 | C3: Incomplete Data
A4: 231 SW 8th Ct | B4: A11907387 | C4: Incomplete Data
A5: 1440-1444 NE 147 STREET | B5: A11900457 | C5: Incomplete Data
A6: 236 NE 1st St | B6: A11917289 | C6: Incomplete Data
A7: 791 NW 22nd Pl | B7: A11771061 | C7: Incomplete Data
A8: 190 NW 57th St | B8: A11509328 | C8: Incomplete Data
A9: 22 NE 59th St | B9: A11611294 | C9: Incomplete Data
A10: 440 SW 5th Ave | B10: A11441503 | C10: Incomplete Data
A11: 5431 & 5433 NW 5th Ave | B11: A11761237 | C11: Incomplete Data
A12: 1080 NW 65th St | B12: A11916482 | C12: Incomplete Data
... A773: 16020 SW 208th Ave | B773: A11930288 | C773: Income anomaly — wrong income data, Issue 6
